<mujoco model="subject_scale_walk">
    <compiler angle="radian" />
    <option collision="predefined">
        <flag energy="enable" />
    </option>
    <size njmax="1000" nconmax="400" nuser_jnt="1" />
    <visual>
        <quality shadowsize="2048" />
        <map force="0.1" fogend="5" />
    </visual>
    <default class="main">
        <joint armature="0.01" damping="0.5" />
        <geom solimp="0.8 0.8 0.01 0.5 2" margin="0.001" material="geom" rgba="0.8 0.6 0.4 1" />
        <site size="0.01 0.005 0.005" />
        <tendon width="0.001" rgba="0.95 0.3 0.3 1" />
        <default class="muscle">
            <general ctrllimited="true" ctrlrange="0 1" dyntype="muscle" gaintype="muscle" biastype="muscle" dynprm="0.01 0.04 0 0 0 0 0 0 0 0" gainprm="0.75 1.05 -1 400 0.5 1.6 1.5 1.3 1.2 0" biasprm="0.75 1.05 -1 400 0.5 1.6 1.5 1.3 1.2 0" />
        </default>
        <default class="motor">
            <general ctrllimited="true" ctrlrange="-1 1" gear="40 0 0 0 0 0" />
        </default>
    </default>
    <asset>
        <texture type="2d" name="texplane" builtin="checker" rgb1="0.2 0.3 0.4" rgb2="0.1 0.15 0.2" width="100" height="100" />
        <texture type="cube" name="texgeom" builtin="flat" mark="cross" rgb1="0.8 0.6 0.4" rgb2="0.8 0.6 0.4" markrgb="1 1 1" width="127" height="762" />
        <material name="MatPlane" texture="texplane" texuniform="true" reflectance="0.5" />
        <material name="geom" texture="texgeom" texuniform="true" />
        <mesh name="r_pelvis" file="Geometry/r_pelvis.stl" scale="1.24463 1.00167 1.19736" />
        <mesh name="l_pelvis" file="Geometry/l_pelvis.stl" scale="1.24463 1.00167 1.19736" />
        <mesh name="sacrum" file="Geometry/sacrum.stl" scale="1.24463 1.00167 1.19736" />
        <mesh name="r_femur" file="Geometry/r_femur.stl" scale="0.958 0.958 0.958" />
        <mesh name="r_tibia" file="Geometry/r_tibia.stl" scale="1.149 1.149 1.149" />
        <mesh name="r_fibula" file="Geometry/r_fibula.stl" scale="1.149 1.149 1.149" />
        <mesh name="r_talus" file="Geometry/r_talus.stl" scale="1.14316 1.66076 1.49753" />
        <mesh name="r_foot" file="Geometry/r_foot.stl" scale="1.14316 1.66076 1.49753" />
        <mesh name="r_bofoot" file="Geometry/r_bofoot.stl" scale="1.14316 1.66076 1.49753" />
        <mesh name="r_patella" file="Geometry/r_patella.stl" scale="0.958 0.958 0.958" />
        <mesh name="l_femur" file="Geometry/l_femur.stl" scale="0.958 0.958 0.958" />
        <mesh name="l_tibia" file="Geometry/l_tibia.stl" scale="1.149 1.149 1.149" />
        <mesh name="l_fibula" file="Geometry/l_fibula.stl" scale="1.149 1.149 1.149" />
        <mesh name="l_talus" file="Geometry/l_talus.stl" scale="1.14316 1.66076 1.49753" />
        <mesh name="l_foot" file="Geometry/l_foot.stl" scale="1.14316 1.66076 1.49753" />
        <mesh name="l_bofoot" file="Geometry/l_bofoot.stl" scale="1.14316 1.66076 1.49753" />
        <mesh name="l_patella" file="Geometry/l_patella.stl" scale="0.958 0.958 0.958" />
        <mesh name="hat_spine" file="Geometry/hat_spine.stl" scale="1.21013 1.17781 1.21013" />
        <mesh name="hat_jaw" file="Geometry/hat_jaw.stl" scale="1.21013 1.17781 1.21013" />
        <mesh name="hat_skull" file="Geometry/hat_skull.stl" scale="1.21013 1.17781 1.21013" />
        <mesh name="hat_ribs_scap" file="Geometry/hat_ribs_scap.stl" scale="1.21013 1.17781 1.21013" />
        <mesh name="humerus_rv" file="Geometry/humerus_rv.stl" scale="1.09817 1.09817 1.09817" />
        <mesh name="ulna_rv" file="Geometry/ulna_rv.stl" scale="1.01397 1.01397 1.01397" />
        <mesh name="radius_rv" file="Geometry/radius_rv.stl" scale="1.01397 1.01397 1.01397" />
        <mesh name="pisiform_rvs" file="Geometry/pisiform_rvs.stl" scale="0.85 0.85 0.85" />
        <mesh name="lunate_rvs" file="Geometry/lunate_rvs.stl" scale="0.85 0.85 0.85" />
        <mesh name="scaphoid_rvs" file="Geometry/scaphoid_rvs.stl" scale="0.85 0.85 0.85" />
        <mesh name="triquetrum_rvs" file="Geometry/triquetrum_rvs.stl" scale="0.85 0.85 0.85" />
        <mesh name="hamate_rvs" file="Geometry/hamate_rvs.stl" scale="0.85 0.85 0.85" />
        <mesh name="capitate_rvs" file="Geometry/capitate_rvs.stl" scale="0.85 0.85 0.85" />
        <mesh name="trapezoid_rvs" file="Geometry/trapezoid_rvs.stl" scale="0.85 0.85 0.85" />
        <mesh name="trapezium_rvs" file="Geometry/trapezium_rvs.stl" scale="0.85 0.85 0.85" />
        <mesh name="metacarpal2_rvs" file="Geometry/metacarpal2_rvs.stl" scale="0.85 0.85 0.85" />
        <mesh name="index_proximal_rvs" file="Geometry/index_proximal_rvs.stl" scale="0.85 0.85 0.85" />
        <mesh name="index_medial_rvs" file="Geometry/index_medial_rvs.stl" scale="0.85 0.85 0.85" />
        <mesh name="index_distal_rvs" file="Geometry/index_distal_rvs.stl" scale="0.85 0.85 0.85" />
        <mesh name="metacarpal3_rvs" file="Geometry/metacarpal3_rvs.stl" scale="0.85 0.85 0.85" />
        <mesh name="middle_proximal_rvs" file="Geometry/middle_proximal_rvs.stl" scale="0.85 0.85 0.85" />
        <mesh name="middle_medial_rvs" file="Geometry/middle_medial_rvs.stl" scale="0.85 0.85 0.85" />
        <mesh name="middle_distal_rvs" file="Geometry/middle_distal_rvs.stl" scale="0.85 0.85 0.85" />
        <mesh name="metacarpal4_rvs" file="Geometry/metacarpal4_rvs.stl" scale="0.85 0.85 0.85" />
        <mesh name="ring_proximal_rvs" file="Geometry/ring_proximal_rvs.stl" scale="0.85 0.85 0.85" />
        <mesh name="ring_medial_rvs" file="Geometry/ring_medial_rvs.stl" scale="0.85 0.85 0.85" />
        <mesh name="ring_distal_rvs" file="Geometry/ring_distal_rvs.stl" scale="0.85 0.85 0.85" />
        <mesh name="metacarpal5_rvs" file="Geometry/metacarpal5_rvs.stl" scale="0.85 0.85 0.85" />
        <mesh name="little_proximal_rvs" file="Geometry/little_proximal_rvs.stl" scale="0.85 0.85 0.85" />
        <mesh name="little_medial_rvs" file="Geometry/little_medial_rvs.stl" scale="0.85 0.85 0.85" />
        <mesh name="little_distal_rvs" file="Geometry/little_distal_rvs.stl" scale="0.85 0.85 0.85" />
        <mesh name="metacarpal1_rvs" file="Geometry/metacarpal1_rvs.stl" scale="0.85 0.85 0.85" />
        <mesh name="thumb_proximal_rvs" file="Geometry/thumb_proximal_rvs.stl" scale="0.85 0.85 0.85" />
        <mesh name="thumb_distal_rvs" file="Geometry/thumb_distal_rvs.stl" scale="0.85 0.85 0.85" />
        <mesh name="humerus_lv" file="Geometry/humerus_lv.stl" scale="1.09817 1.09817 1.09817" />
        <mesh name="ulna_lv" file="Geometry/ulna_lv.stl" scale="1.01397 1.01397 1.01397" />
        <mesh name="radius_lv" file="Geometry/radius_lv.stl" scale="1.01397 1.01397 1.01397" />
        <mesh name="pisiform_lvs" file="Geometry/pisiform_lvs.stl" scale="0.85 0.85 0.85" />
        <mesh name="lunate_lvs" file="Geometry/lunate_lvs.stl" scale="0.85 0.85 0.85" />
        <mesh name="scaphoid_lvs" file="Geometry/scaphoid_lvs.stl" scale="0.85 0.85 0.85" />
        <mesh name="triquetrum_lvs" file="Geometry/triquetrum_lvs.stl" scale="0.85 0.85 0.85" />
        <mesh name="hamate_lvs" file="Geometry/hamate_lvs.stl" scale="0.85 0.85 0.85" />
        <mesh name="capitate_lvs" file="Geometry/capitate_lvs.stl" scale="0.85 0.85 0.85" />
        <mesh name="trapezoid_lvs" file="Geometry/trapezoid_lvs.stl" scale="0.85 0.85 0.85" />
        <mesh name="trapezium_lvs" file="Geometry/trapezium_lvs.stl" scale="0.85 0.85 0.85" />
        <mesh name="metacarpal2_lvs" file="Geometry/metacarpal2_lvs.stl" scale="0.85 0.85 0.85" />
        <mesh name="index_proximal_lvs" file="Geometry/index_proximal_lvs.stl" scale="0.85 0.85 0.85" />
        <mesh name="index_medial_lvs" file="Geometry/index_medial_lvs.stl" scale="0.85 0.85 0.85" />
        <mesh name="index_distal_lvs" file="Geometry/index_distal_lvs.stl" scale="0.85 0.85 0.85" />
        <mesh name="metacarpal3_lvs" file="Geometry/metacarpal3_lvs.stl" scale="0.85 0.85 0.85" />
        <mesh name="middle_proximal_lvs" file="Geometry/middle_proximal_lvs.stl" scale="0.85 0.85 0.85" />
        <mesh name="middle_medial_lvs" file="Geometry/middle_medial_lvs.stl" scale="0.85 0.85 0.85" />
        <mesh name="middle_distal_lvs" file="Geometry/middle_distal_lvs.stl" scale="0.85 0.85 0.85" />
        <mesh name="metacarpal4_lvs" file="Geometry/metacarpal4_lvs.stl" scale="0.85 0.85 0.85" />
        <mesh name="ring_proximal_lvs" file="Geometry/ring_proximal_lvs.stl" scale="0.85 0.85 0.85" />
        <mesh name="ring_medial_lvs" file="Geometry/ring_medial_lvs.stl" scale="0.85 0.85 0.85" />
        <mesh name="ring_distal_lvs" file="Geometry/ring_distal_lvs.stl" scale="0.85 0.85 0.85" />
        <mesh name="metacarpal5_lvs" file="Geometry/metacarpal5_lvs.stl" scale="0.85 0.85 0.85" />
        <mesh name="little_proximal_lvs" file="Geometry/little_proximal_lvs.stl" scale="0.85 0.85 0.85" />
        <mesh name="little_medial_lvs" file="Geometry/little_medial_lvs.stl" scale="0.85 0.85 0.85" />
        <mesh name="little_distal_lvs" file="Geometry/little_distal_lvs.stl" scale="0.85 0.85 0.85" />
        <mesh name="metacarpal1_lvs" file="Geometry/metacarpal1_lvs.stl" scale="0.85 0.85 0.85" />
        <mesh name="thumb_proximal_lvs" file="Geometry/thumb_proximal_lvs.stl" scale="0.85 0.85 0.85" />
        <mesh name="thumb_distal_lvs" file="Geometry/thumb_distal_lvs.stl" scale="0.85 0.85 0.85" />
    </asset>
    <worldbody>
        <geom name="floor" size="10 10 0.125" type="plane" material="MatPlane" />
        <camera name="for_testing" pos="2 -6 1" quat="0.707388 0.706825 0 0" />
        <body name="sphere" pos="0 0 0" mocap="true">
            <inertial pos="0 0 0" mass="0.0335103" diaginertia="0.001 0.001 0.001" />
            <geom size="0.02" contype="0" conaffinity="0" rgba="1 0 0 1" />
        </body>
        <body name="pFootLeft" pos="0 0 0" mocap="true">
            <inertial pos="0 0 0" mass="0.0335103" diaginertia="0.001 0.001 0.001" />
            <geom size="0.02" contype="0" conaffinity="0" rgba="0 1 0 1" />
        </body>
        <body name="pFootRight" pos="0 0 0" mocap="true">
            <inertial pos="0 0 0" mass="0.0335103" diaginertia="0.001 0.001 0.001" />
            <geom size="0.02" contype="0" conaffinity="0" rgba="1 1 0 1" />
        </body>
        <body name="pelvis" pos="0 0 0" quat="0.707107 0.707107 0 0">
            <inertial pos="-0.0879955 0 0" mass="13.298" diaginertia="0.160304 0.160304 0.081507" />
            <joint name="pelvis_tz" pos="0 0 0" axis="0 1 0" type="slide" limited="true" range="-3 3" armature="0" damping="0" />
            <joint name="pelvis_ty" pos="0 0 0" axis="0 0 -1" type="slide" limited="true" range="-1 2" armature="0" damping="0" />
            <joint name="pelvis_tx" pos="0 0 0" axis="1 0 0" type="slide" limited="true" range="-5 5" armature="0" damping="0" />
            <joint name="pelvis_tilt" pos="0 0 0" axis="0 0 -1" limited="true" range="-1.5708 1.5708" armature="0" damping="0" />
            <joint name="pelvis_list" pos="0 0 0" axis="1 0 0" limited="true" range="-1.5708 1.5708" armature="0" damping="0" />
            <joint name="pelvis_rotation" pos="0 0 0" axis="0 1 0" limited="true" range="-1.5708 1.5708" armature="0" damping="0" />
            <geom name="r_pelvis" type="mesh" mesh="r_pelvis" />
            <geom name="l_pelvis" type="mesh" mesh="l_pelvis" />
            <geom name="sacrum" type="mesh" mesh="sacrum" />
            <light pos="0 0 4" dir="0 0 -1" diffuse="0.8 0.8 0.8" mode="trackcom" />
            <body name="femur_r" pos="-0.0700429 -0.0786209 0.0925079">
                <inertial pos="0 -0.16286 0" quat="0.5 0.5 -0.5 0.5" mass="10.5027" diaginertia="0.146325 0.13876 0.0363739" />
                <joint name="hip_flexion_r" pos="0 0 0" axis="0 0 1" limited="true" range="-0.523599 2.0944" />
                <joint name="hip_adduction_r" pos="0 0 0" axis="1 0 0" limited="true" range="-0.872665 0.523599" />
                <joint name="hip_rotation_r" pos="0 0 0" axis="0 1 0" limited="true" range="-0.698132 0.698132" />
                <geom name="r_femur" type="mesh" mesh="r_femur" />
                <body name="tibia_r" pos="0.00154466 -0.386764 -0.000928534">
                    <inertial pos="0 -0.214518 0" quat="0.5 0.5 -0.5 0.5" mass="4.18632" diaginertia="0.076175 0.0751316 0.0076026" />
                    <joint name="knee_angle_r_translation2" pos="0 0 0" axis="0.992246 0.123982 -0.00878916" type="slide" limited="true" range="7.69254e-11 0.006792" />
                    <joint name="knee_angle_r_translation1" pos="0 0 0" axis="-0.124293 0.989762 -0.0701648" type="slide" limited="true" range="9.53733e-08 0.00159883" />
                    <joint name="knee_angle_r" pos="0 0 0" axis="-3.98373e-10 -0.0707131 -0.997497" limited="true" range="0 2.0944" />
                    <joint name="knee_angle_r_rotation2" pos="0 0 0" axis="0.992246 0.123982 -0.00878916" limited="true" range="-0.00167821 0.0335354" />
                    <joint name="knee_angle_r_rotation3" pos="0 0 0" axis="-0.124293 0.989762 -0.0701648" limited="true" range="1.08939e-08 0.262788" />
                    <geom name="r_tibia" type="mesh" mesh="r_tibia" />
                    <geom name="r_fibula" type="mesh" mesh="r_fibula" />
                    <body name="talus_r" pos="-0.01149 -0.4596 0">
                        <inertial pos="0 0 0" mass="0.112915" diaginertia="0.00280824 0.00214191 0.00214191" />
                        <joint name="ankle_angle_r" pos="0 0 0" axis="-0.105014 -0.174022 0.979126" limited="true" range="-0.698132 0.523599" />
                        <geom name="r_talus" type="mesh" mesh="r_talus" />
                        <body name="calcn_r" pos="-0.0557517 -0.0696689 0.0118604">
                            <inertial pos="0.114316 0.0498228 0" quat="0.5 0.5 0.5 0.5" mass="1.41144" diaginertia="0.00668762 0.00668762 0.00393153" />
                            <joint name="subtalar_angle_r" pos="0 0 0" axis="0.78718 0.604747 -0.120949" limited="true" range="-0.349066 0.349066" />
                            <geom name="r_foot" type="mesh" mesh="r_foot" />
                            <geom name="r_foot_box" size="0.08 0.005 0.07" pos="0.12 -0.01 0.01" type="box" rgba="0 0.9 0 0.1" />
                            <site name="r_foot_box-P1" pos="0.04 -0.01 -0.06" />
                            <site name="r_foot_box-P2" pos="0.04 -0.01 0.08" />
                            <site name="r_foot_box-P3" pos="0.2 -0.01 -0.06" />
                            <site name="r_foot_box-P4" pos="0.2 -0.01 0.08" />
                            <body name="toes_r" pos="0.204396 -0.00332152 0.00161733">
                                <inertial pos="0.0395532 0.00996457 -0.0262067" quat="0.5 0.5 0.5 0.5" mass="0.244574" diaginertia="0.001 0.001 0.001" />
                                <joint name="mtp_angle_r" pos="0 0 0" axis="0.580954 0 -0.813936" limited="true" range="-0.523599 0.523599" />
                                <geom name="r_bofoot" type="mesh" mesh="r_bofoot" />
                            </body>
                        </body>
                    </body>
                </body>
                <body name="patella_r" pos="-0.00775022 -0.390826 0.0001155">
                    <inertial pos="0.0017244 0.0252912 0" quat="0.5 0.5 0.5 0.5" mass="0.0973328" diaginertia="0.001 0.001 0.001" />
                    <joint name="knee_angle_r_beta_translation2" pos="0 0 0" axis="0 1 0" type="slide" limited="true" range="-0.0408267 -0.0108281" />
                    <joint name="knee_angle_r_beta_translation1" pos="0 0 0" axis="1 0 0" type="slide" limited="true" range="-0.0227731 0.0524192" />
                    <joint name="knee_angle_r_beta_rotation1" pos="0 0 0" axis="0 0 1" limited="true" range="-1.79241 0.010506" />
                    <geom name="r_patella" type="mesh" mesh="r_patella" />
                </body>
            </body>
            <body name="femur_l" pos="-0.0700429 -0.0786209 -0.0925079">
                <inertial pos="0 -0.16286 0" quat="0.5 0.5 -0.5 0.5" mass="10.5027" diaginertia="0.146325 0.13876 0.0363739" />
                <joint name="hip_flexion_l" pos="0 0 0" axis="0 0 1" limited="true" range="-0.523599 2.0944" />
                <joint name="hip_adduction_l" pos="0 0 0" axis="-1 0 0" limited="true" range="-0.872665 0.523599" />
                <joint name="hip_rotation_l" pos="0 0 0" axis="0 -1 0" limited="true" range="-0.698132 0.698132" />
                <geom name="l_femur" type="mesh" mesh="l_femur" />
                <body name="tibia_l" pos="0.00154466 -0.386764 0.000928534">
                    <inertial pos="0 -0.214518 0" quat="0.5 0.5 -0.5 0.5" mass="4.18632" diaginertia="0.076175 0.0751316 0.0076026" />
                    <joint name="knee_angle_l_translation2" pos="0 0 0" axis="-0.992246 -0.123982 -0.00878916" type="slide" limited="true" range="-0.006792 -7.69254e-11" />
                    <joint name="knee_angle_l_translation1" pos="0 0 0" axis="-0.124293 0.989762 0.0701648" type="slide" limited="true" range="9.53733e-08 0.00159883" />
                    <joint name="knee_angle_l" pos="0 0 0" axis="3.98373e-10 0.0707131 -0.997497" limited="true" range="0 2.0944" />
                    <joint name="knee_angle_l_rotation2" pos="0 0 0" axis="-0.992246 -0.123982 -0.00878916" limited="true" range="-0.00167821 0.0335354" />
                    <joint name="knee_angle_l_rotation3" pos="0 0 0" axis="-0.124293 0.989762 0.0701648" limited="true" range="-0.262788 -1.08939e-08" />
                    <geom name="l_tibia" type="mesh" mesh="l_tibia" />
                    <geom name="l_fibula" type="mesh" mesh="l_fibula" />
                    <body name="talus_l" pos="-0.01149 -0.4596 0">
                        <inertial pos="0 0 0" mass="0.112915" diaginertia="0.00280824 0.00214191 0.00214191" />
                        <joint name="ankle_angle_l" pos="0 0 0" axis="0.105014 0.174022 0.979126" limited="true" range="-0.698132 0.523599" />
                        <geom name="l_talus" type="mesh" mesh="l_talus" />
                        <body name="calcn_l" pos="-0.0557517 -0.0696689 -0.0118604">
                            <inertial pos="0.114316 0.0498228 0" quat="0.5 0.5 0.5 0.5" mass="1.41144" diaginertia="0.00668762 0.00668762 0.00393153" />
                            <joint name="subtalar_angle_l" pos="0 0 0" axis="-0.78718 -0.604747 -0.120949" limited="true" range="-0.349066 0.349066" />
                            <geom name="l_foot" type="mesh" mesh="l_foot" />
                            <geom name="l_foot_box" size="0.08 0.005 0.07" pos="0.12 -0.01 -0.01" type="box" rgba="0 0.9 0 0.1" />
                            <site name="l_foot_box-P1" pos="0.04 -0.01 -0.08" />
                            <site name="l_foot_box-P2" pos="0.04 -0.01 0.06" />
                            <site name="l_foot_box-P3" pos="0.2 -0.01 -0.08" />
                            <site name="l_foot_box-P4" pos="0.2 -0.01 0.06" />
                            <body name="toes_l" pos="0.204396 -0.00332152 -0.00161733">
                                <inertial pos="0.0395532 0.00996457 0.0262067" quat="0.5 0.5 0.5 0.5" mass="0.244574" diaginertia="0.001 0.001 0.001" />
                                <joint name="mtp_angle_l" pos="0 0 0" axis="-0.580954 0 -0.813936" limited="true" range="-0.523599 0.523599" />
                                <geom name="l_bofoot" type="mesh" mesh="l_bofoot" />
                            </body>
                        </body>
                    </body>
                </body>
                <body name="patella_l" pos="-0.00775022 -0.390826 -0.0001155">
                    <inertial pos="0.0017244 0.0252912 0" quat="0.5 0.5 0.5 0.5" mass="0.0973328" diaginertia="0.001 0.001 0.001" />
                    <joint name="knee_angle_l_beta_translation2" pos="0 0 0" axis="0 1 0" type="slide" limited="true" range="-0.0408267 -0.0108281" />
                    <joint name="knee_angle_l_beta_translation1" pos="0 0 0" axis="1 0 0" type="slide" limited="true" range="-0.0227731 0.0524192" />
                    <joint name="knee_angle_l_beta_rotation1" pos="0 0 0" axis="0 0 1" limited="true" range="-1.79241 0.010506" />
                    <geom name="l_patella" type="mesh" mesh="l_patella" />
                </body>
            </body>
            <body name="torso" pos="-0.125334 0.0816359 0">
                <inertial pos="-0.0363039 0.376899 0" quat="0.707107 0.707107 0 0" mass="30.2913" diaginertia="2.34257 2.34257 1.24925" />
                <joint name="lumbar_extension" pos="0 0 0" axis="0 0 1" limited="true" range="-1.5708 1.5708" />
                <joint name="lumbar_bending" pos="0 0 0" axis="1 0 0" limited="true" range="-1.5708 1.5708" />
                <joint name="lumbar_rotation" pos="0 0 0" axis="0 1 0" limited="true" range="-1.5708 1.5708" />
                <geom name="hat_spine" type="mesh" mesh="hat_spine" />
                <geom name="hat_jaw" type="mesh" mesh="hat_jaw" />
                <geom name="hat_skull" type="mesh" mesh="hat_skull" />
                <geom name="hat_ribs_scap" type="mesh" mesh="hat_ribs_scap" />
                <body name="humerus_r" pos="0.00381796 0.437556 0.205722">
                    <inertial pos="0 -0.180651 0" quat="0.5 0.5 -0.5 0.5" mass="2.295" diaginertia="0.0182594 0.0162672 0.00561169" />
                    <joint name="arm_flex_r" pos="0 0 0" axis="0 0 1" limited="true" range="-1.5708 1.5708" />
                    <joint name="arm_add_r" pos="0 0 0" axis="1 0 0" limited="true" range="-2.0944 1.5708" />
                    <joint name="arm_rot_r" pos="0 0 0" axis="0 1 0" limited="true" range="-1.5708 1.5708" />
                    <geom name="humerus_rv" type="mesh" mesh="humerus_rv" />
                    <body name="ulna_r" pos="0.0144343 -0.314376 -0.0105369">
                        <inertial pos="0 -0.122209 0" quat="0.5 0.5 -0.5 0.5" mass="0.685959" diaginertia="0.00373003 0.00343864 0.001" />
                        <joint name="elbow_flex_r" pos="0 0 0" axis="0.226047 0.022269 0.973862" limited="true" range="0 2.618" />
                        <geom name="ulna_rv" type="mesh" mesh="ulna_rv" />
                        <body name="radius_r" pos="-0.00682098 -0.0131887 0.0264474">
                            <inertial pos="0 -0.122209 0" quat="0.5 0.5 -0.5 0.5" mass="0.685959" diaginertia="0.00373003 0.00343864 0.001" />
                            <joint name="pro_sup_r" pos="0 0 0" axis="0.056398 0.998406 0.001952" limited="true" range="0 1.5708" />
                            <geom name="radius_rv" type="mesh" mesh="radius_rv" />
                            <body name="hand_r" pos="-0.00891989 -0.239136 0.0138001">
                                <inertial pos="0 -0.068095 0" quat="0.5 0.5 -0.5 0.5" mass="0.516586" diaginertia="0.00151306 0.0010072 0.001" />
                                <joint name="wrist_flex_r" pos="0 0 0" axis="0 0 1" limited="true" range="-1.22173 1.22173" />
                                <joint name="wrist_dev_r" pos="0 0 0" axis="1 0 0" limited="true" range="-0.436332 0.610865" />
                                <geom name="pisiform_rvs" type="mesh" mesh="pisiform_rvs" />
                                <geom name="lunate_rvs" type="mesh" mesh="lunate_rvs" />
                                <geom name="scaphoid_rvs" type="mesh" mesh="scaphoid_rvs" />
                                <geom name="triquetrum_rvs" type="mesh" mesh="triquetrum_rvs" />
                                <geom name="hamate_rvs" type="mesh" mesh="hamate_rvs" />
                                <geom name="capitate_rvs" type="mesh" mesh="capitate_rvs" />
                                <geom name="trapezoid_rvs" type="mesh" mesh="trapezoid_rvs" />
                                <geom name="trapezium_rvs" type="mesh" mesh="trapezium_rvs" />
                                <geom name="metacarpal2_rvs" type="mesh" mesh="metacarpal2_rvs" />
                                <geom name="index_proximal_rvs" type="mesh" mesh="index_proximal_rvs" />
                                <geom name="index_medial_rvs" type="mesh" mesh="index_medial_rvs" />
                                <geom name="index_distal_rvs" type="mesh" mesh="index_distal_rvs" />
                                <geom name="metacarpal3_rvs" type="mesh" mesh="metacarpal3_rvs" />
                                <geom name="middle_proximal_rvs" type="mesh" mesh="middle_proximal_rvs" />
                                <geom name="middle_medial_rvs" type="mesh" mesh="middle_medial_rvs" />
                                <geom name="middle_distal_rvs" type="mesh" mesh="middle_distal_rvs" />
                                <geom name="metacarpal4_rvs" type="mesh" mesh="metacarpal4_rvs" />
                                <geom name="ring_proximal_rvs" type="mesh" mesh="ring_proximal_rvs" />
                                <geom name="ring_medial_rvs" type="mesh" mesh="ring_medial_rvs" />
                                <geom name="ring_distal_rvs" type="mesh" mesh="ring_distal_rvs" />
                                <geom name="metacarpal5_rvs" type="mesh" mesh="metacarpal5_rvs" />
                                <geom name="little_proximal_rvs" type="mesh" mesh="little_proximal_rvs" />
                                <geom name="little_medial_rvs" type="mesh" mesh="little_medial_rvs" />
                                <geom name="little_distal_rvs" type="mesh" mesh="little_distal_rvs" />
                                <geom name="metacarpal1_rvs" type="mesh" mesh="metacarpal1_rvs" />
                                <geom name="thumb_proximal_rvs" type="mesh" mesh="thumb_proximal_rvs" />
                                <geom name="thumb_distal_rvs" type="mesh" mesh="thumb_distal_rvs" />
                            </body>
                        </body>
                    </body>
                </body>
                <body name="humerus_l" pos="0.00381796 0.437556 -0.205722">
                    <inertial pos="0 -0.180651 0" quat="0.5 0.5 -0.5 0.5" mass="2.295" diaginertia="0.0182594 0.0162672 0.00561169" />
                    <joint name="arm_flex_l" pos="0 0 0" axis="0 0 1" limited="true" range="-1.5708 1.5708" />
                    <joint name="arm_add_l" pos="0 0 0" axis="-1 0 0" limited="true" range="-2.0944 1.5708" />
                    <joint name="arm_rot_l" pos="0 0 0" axis="0 -1 0" limited="true" range="-1.5708 1.5708" />
                    <geom name="humerus_lv" type="mesh" mesh="humerus_lv" />
                    <body name="ulna_l" pos="0.0144343 -0.314376 0.0105369">
                        <inertial pos="0 -0.122209 0" quat="0.5 0.5 -0.5 0.5" mass="0.685959" diaginertia="0.00373003 0.00343864 0.001" />
                        <joint name="elbow_flex_l" pos="0 0 0" axis="-0.226047 -0.022269 0.973862" limited="true" range="0 2.618" />
                        <geom name="ulna_lv" type="mesh" mesh="ulna_lv" />
                        <body name="radius_l" pos="-0.00682098 -0.0131887 -0.0264474">
                            <inertial pos="0 -0.122209 0" quat="0.5 0.5 -0.5 0.5" mass="0.685959" diaginertia="0.00373003 0.00343864 0.001" />
                            <joint name="pro_sup_l" pos="0 0 0" axis="-0.056398 -0.998406 0.001952" limited="true" range="0 1.5708" />
                            <geom name="radius_lv" type="mesh" mesh="radius_lv" />
                            <body name="hand_l" pos="-0.00891989 -0.239136 -0.0138001">
                                <inertial pos="0 -0.068095 0" quat="0.5 0.5 -0.5 0.5" mass="0.516586" diaginertia="0.00151306 0.0010072 0.001" />
                                <joint name="wrist_flex_l" pos="0 0 0" axis="0 0 1" limited="true" range="-1.22173 1.22173" />
                                <joint name="wrist_dev_l" pos="0 0 0" axis="-1 0 0" limited="true" range="-0.436332 0.610865" />
                                <geom name="pisiform_lvs" type="mesh" mesh="pisiform_lvs" />
                                <geom name="lunate_lvs" type="mesh" mesh="lunate_lvs" />
                                <geom name="scaphoid_lvs" type="mesh" mesh="scaphoid_lvs" />
                                <geom name="triquetrum_lvs" type="mesh" mesh="triquetrum_lvs" />
                                <geom name="hamate_lvs" type="mesh" mesh="hamate_lvs" />
                                <geom name="capitate_lvs" type="mesh" mesh="capitate_lvs" />
                                <geom name="trapezoid_lvs" type="mesh" mesh="trapezoid_lvs" />
                                <geom name="trapezium_lvs" type="mesh" mesh="trapezium_lvs" />
                                <geom name="metacarpal2_lvs" type="mesh" mesh="metacarpal2_lvs" />
                                <geom name="index_proximal_lvs" type="mesh" mesh="index_proximal_lvs" />
                                <geom name="index_medial_lvs" type="mesh" mesh="index_medial_lvs" />
                                <geom name="index_distal_lvs" type="mesh" mesh="index_distal_lvs" />
                                <geom name="metacarpal3_lvs" type="mesh" mesh="metacarpal3_lvs" />
                                <geom name="middle_proximal_lvs" type="mesh" mesh="middle_proximal_lvs" />
                                <geom name="middle_medial_lvs" type="mesh" mesh="middle_medial_lvs" />
                                <geom name="middle_distal_lvs" type="mesh" mesh="middle_distal_lvs" />
                                <geom name="metacarpal4_lvs" type="mesh" mesh="metacarpal4_lvs" />
                                <geom name="ring_proximal_lvs" type="mesh" mesh="ring_proximal_lvs" />
                                <geom name="ring_medial_lvs" type="mesh" mesh="ring_medial_lvs" />
                                <geom name="ring_distal_lvs" type="mesh" mesh="ring_distal_lvs" />
                                <geom name="metacarpal5_lvs" type="mesh" mesh="metacarpal5_lvs" />
                                <geom name="little_proximal_lvs" type="mesh" mesh="little_proximal_lvs" />
                                <geom name="little_medial_lvs" type="mesh" mesh="little_medial_lvs" />
                                <geom name="little_distal_lvs" type="mesh" mesh="little_distal_lvs" />
                                <geom name="metacarpal1_lvs" type="mesh" mesh="metacarpal1_lvs" />
                                <geom name="thumb_proximal_lvs" type="mesh" mesh="thumb_proximal_lvs" />
                                <geom name="thumb_distal_lvs" type="mesh" mesh="thumb_distal_lvs" />
                            </body>
                        </body>
                    </body>
                </body>
            </body>
        </body>
    </worldbody>
    <equality>
        <joint name="knee_angle_r_translation2_constraint" joint1="knee_angle_r_translation2" joint2="knee_angle_r" polycoef="7.69254e-11 0.00587971 -0.00125622 -2.61846e-06 6.24355e-07" solimp="0.9999 0.9999 0.001 0.5 2" />
        <joint name="knee_angle_r_translation1_constraint" joint1="knee_angle_r_translation1" joint2="knee_angle_r" polycoef="9.53733e-08 0.00312879 -0.00230804 0.000561561 5.68366e-07" solimp="0.9999 0.9999 0.001 0.5 2" />
        <joint name="knee_angle_r_rotation2_constraint" joint1="knee_angle_r_rotation2" joint2="knee_angle_r" polycoef="-1.47325e-08 0.0791 -0.0328478 -0.0252183 0.0108321" solimp="0.9999 0.9999 0.001 0.5 2" />
        <joint name="knee_angle_r_rotation3_constraint" joint1="knee_angle_r_rotation3" joint2="knee_angle_r" polycoef="1.08939e-08 0.369499 -0.169478 0.0251643 3.50498e-07" solimp="0.9999 0.9999 0.001 0.5 2" />
        <joint name="knee_angle_r_beta_translation2_constraint" joint1="knee_angle_r_beta_translation2" joint2="knee_angle_r" polycoef="-0.0108281 -0.0487847 0.00927644 0.0131673 -0.00349673" solimp="0.9999 0.9999 0.001 0.5 2" />
        <joint name="knee_angle_r_beta_translation1_constraint" joint1="knee_angle_r_beta_translation1" joint2="knee_angle_r" polycoef="0.0524192 -0.0150188 -0.0340522 0.0133393 -0.000879151" solimp="0.9999 0.9999 0.001 0.5 2" />
        <joint name="knee_angle_r_beta_rotation1_constraint" joint1="knee_angle_r_beta_rotation1" joint2="knee_angle_r" polycoef="0.010506 0.0247615 -1.31647 0.716337 -0.138302" solimp="0.9999 0.9999 0.001 0.5 2" />
        <joint name="subtalar_angle_r_constraint" joint1="subtalar_angle_r" polycoef="0 0 0 0 0" />
        <joint name="mtp_angle_r_constraint" joint1="mtp_angle_r" polycoef="0 0 0 0 0" />
        <joint name="knee_angle_l_translation2_constraint" joint1="knee_angle_l_translation2" joint2="knee_angle_l" polycoef="-7.69254e-11 -0.00587971 0.00125622 2.61846e-06 -6.24355e-07" solimp="0.9999 0.9999 0.001 0.5 2" />
        <joint name="knee_angle_l_translation1_constraint" joint1="knee_angle_l_translation1" joint2="knee_angle_l" polycoef="9.53733e-08 0.00312879 -0.00230804 0.000561561 5.68366e-07" solimp="0.9999 0.9999 0.001 0.5 2" />
        <joint name="knee_angle_l_rotation2_constraint" joint1="knee_angle_l_rotation2" joint2="knee_angle_l" polycoef="-1.47325e-08 0.0791 -0.0328478 -0.0252183 0.0108321" solimp="0.9999 0.9999 0.001 0.5 2" />
        <joint name="knee_angle_l_rotation3_constraint" joint1="knee_angle_l_rotation3" joint2="knee_angle_l" polycoef="-1.08939e-08 -0.369499 0.169478 -0.0251643 -3.50498e-07" solimp="0.9999 0.9999 0.001 0.5 2" />
        <joint name="knee_angle_l_beta_translation2_constraint" joint1="knee_angle_l_beta_translation2" joint2="knee_angle_l" polycoef="-0.0108281 -0.0487847 0.00927644 0.0131673 -0.00349673" solimp="0.9999 0.9999 0.001 0.5 2" />
        <joint name="knee_angle_l_beta_translation1_constraint" joint1="knee_angle_l_beta_translation1" joint2="knee_angle_l" polycoef="0.0524192 -0.0150188 -0.0340522 0.0133393 -0.000879151" solimp="0.9999 0.9999 0.001 0.5 2" />
        <joint name="knee_angle_l_beta_rotation1_constraint" joint1="knee_angle_l_beta_rotation1" joint2="knee_angle_l" polycoef="0.010506 0.0247615 -1.31647 0.716337 -0.138302" solimp="0.9999 0.9999 0.001 0.5 2" />
        <joint name="subtalar_angle_l_constraint" joint1="subtalar_angle_l" polycoef="0 0 0 0 0" />
        <joint name="mtp_angle_l_constraint" joint1="mtp_angle_l" polycoef="0 0 0 0 0" />
        <joint name="wrist_flex_r_constraint" joint1="wrist_flex_r" polycoef="0 0 0 0 0" />
        <joint name="wrist_dev_r_constraint" joint1="wrist_dev_r" polycoef="0 0 0 0 0" />
        <joint name="wrist_flex_l_constraint" joint1="wrist_flex_l" polycoef="0 0 0 0 0" />
        <joint name="wrist_dev_l_constraint" joint1="wrist_dev_l" polycoef="0 0 0 0 0" />
        <weld name="origin_to_worldbody" body1="pelvis" relpose="0 0 0 0.707107 -0.707107 0 0" active="false" />
    </equality>
</mujoco>
